Workbook

Sheet SIMPLES NACIONAL
G1: =G3/PREMISSAS!$C$12 -> 3067.4847 | H1: =G1/30*7 -> 715.74642 | I1: =I3/PREMISSAS!$C$12 -> 3680.9816 | J1: =I1*30*7 -> 773006.13 | K1: =K3/PREMISSAS!$C$12 -> 4294.4785 | L1: =K1*30*7 -> 901840.49
B2: DEMONSTRAÇÃO DE RESULTADO DO EXERCÍCIO - DRE | C2: 150K | D2: 150K - AV% | E2: 200K | F2: 200K - AV% | G2: 250K | H2: 250K - AV% | I2: 300K | J2: 300K - AV% | K2: 350K | L2: 350K - AV%
B3: Receita Vendas | C3: 150000 | D3: =C3/C$3 -> 1 | E3: 200000 | F3: =E3/E$3 -> 1 | G3: 250000 | H3: =G3/G$3 -> 1 | I3: 300000 | J3: =I3/I$3 -> 1 | K3: 350000 | L3: =K3/K$3 -> 1
B4: Receita Serviços (Taxa de Entrega) | C4: =C3/PREMISSAS!$C$12*PREMISSAS!$C$27*(1-PREMISSAS!$C$17)*PREMISSAS!$C$16 -> 15349.693 | D4: =C4/C$3 -> 0.10233129 | E4: =E3/PREMISSAS!$C$12*PREMISSAS!$C$27*(1-PREMISSAS!$C$17)*PREMISSAS!$C$16 -> 20466.258 | F4: =E4/E$3 -> 0.10233129 | G4: =G3/PREMISSAS!$C$12*PREMISSAS!$C$27*(1-PREMISSAS!$C$17)*PREMISSAS!$C$16 -> 25582.822 | H4: =G4/G$3 -> 0.10233129 | I4: =I3/PREMISSAS!$C$12*PREMISSAS!$C$27*(1-PREMISSAS!$C$17)*PREMISSAS!$C$16 -> 30699.387 | J4: =I4/I$3 -> 0.10233129 | K4: =K3/PREMISSAS!$C$12*PREMISSAS!$C$27*(1-PREMISSAS!$C$17)*PREMISSAS!$C$16 -> 35815.951 | L4: =K4/K$3 -> 0.10233129
B5: = Receita Operacional Bruta | C5: =SUM(C3:C4) -> 165349.69 | D5: =C5/C$3 -> 1.1023313 | E5: =SUM(E3:E4) -> 220466.26 | F5: =E5/E$3 -> 1.1023313 | G5: =SUM(G3:G4) -> 275582.82 | H5: =G5/G$3 -> 1.1023313 | I5: =SUM(I3:I4) -> 330699.39 | J5: =I5/I$3 -> 1.1023313 | K5: =SUM(K3:K4) -> 385815.95 | L5: =K5/K$3 -> 1.1023313
B6: (-) Impostos | C6: =-C3*PREMISSAS!$F$17 -> -15804.674 | D6: =C6/C$3 -> -0.10536449 | E6: =-E3*PREMISSAS!$F$18 -> -23497.898 | F6: =E6/E$3 -> -0.11748949 | G6: =-G3*PREMISSAS!$F$19 -> -31191.123 | H6: =G6/G$3 -> -0.12476449 | I6: =-I3*PREMISSAS!$F$20 -> -29830.601 | J6: =I6/I$3 -> -0.099435337 | K6: =-K3*PREMISSAS!$F$21 -> -40052.368 | L6: =K6/K$3 -> -0.11443534
B7: = Receita Líquida | C7: =SUM(C5:C6) -> 149545.02 | D7: =C7/C$3 -> 0.9969668 | E7: =SUM(E5:E6) -> 196968.36 | F7: =E7/E$3 -> 0.9848418 | G7: =SUM(G5:G6) -> 244391.7 | H7: =G7/G$3 -> 0.9775668 | I7: =SUM(I5:I6) -> 300868.79 | J7: =I7/I$3 -> 1.002896 | K7: =SUM(K5:K6) -> 345763.58 | L7: =K7/K$3 -> 0.98789595
B8: = Lucro Bruto
B9: = CMV com Frete | C9: =-(C3*PREMISSAS!$I$12+C3*PREMISSAS!$I$13) -> -53100 | D9: =C9/C$3 -> -0.354 | E9: =-(E3*PREMISSAS!$I$12+E3*PREMISSAS!$I$13) -> -70800 | F9: =E9/E$3 -> -0.354 | G9: =-(G3*PREMISSAS!$I$12+G3*PREMISSAS!$I$13) -> -88500 | H9: =G9/G$3 -> -0.354 | I9: =-(I3*PREMISSAS!$I$12+I3*PREMISSAS!$I$13) -> -106200 | J9: =I9/I$3 -> -0.354 | K9: =-(K3*PREMISSAS!$I$12+K3*PREMISSAS!$I$13) -> -123900 | L9: =K9/K$3 -> -0.354
B10: = Lucro Bruto
B11: = Lucro Bruto | C11: =C7+C9 -> 96445.02 | D11: =C11/C$3 -> 0.6429668 | E11: =E7+E9 -> 126168.36 | F11: =E11/E$3 -> 0.6308418 | G11: =G7+G9 -> 155891.7 | H11: =G11/G$3 -> 0.6235668 | I11: =I7+I9 -> 194668.79 | J11: =I11/I$3 -> 0.64889595 | K11: =K7+K9 -> 221863.58 | L11: =K11/K$3 -> 0.63389595
B12: (-) Custo pessoal salão | C12: =-((PREMISSAS!L13*PREMISSAS!M13)+(PREMISSAS!L14*PREMISSAS!M14)) -> -20180 | D12: =C12/C$3 -> -0.13453333 | E12: =-((PREMISSAS!L17*PREMISSAS!M17)+(PREMISSAS!L18*PREMISSAS!M18)) -> -23216 | F12: =E12/E$3 -> -0.11608 | G12: =-((PREMISSAS!L21*PREMISSAS!M21)+(PREMISSAS!L22*PREMISSAS!M22)) -> -28216 | H12: =G12/G$3 -> -0.112864 | I12: =-((PREMISSAS!L25*PREMISSAS!M25)+(PREMISSAS!L26*PREMISSAS!M26)) -> -31252 | J12: =I12/I$3 -> -0.10417333 | K12: =-((PREMISSAS!L29*PREMISSAS!M29)+(PREMISSAS!L30*PREMISSAS!M30)) -> -34288 | L12: =K12/K$3 -> -0.097965714
B13: (-) Custo especialistas | C13: =-C3/PREMISSAS!C12*PREMISSAS!C27*PREMISSAS!M15 -> -15349.693 | D13: =C13/C$3 -> -0.10233129 | E13: =-E3/PREMISSAS!C12*PREMISSAS!C27*PREMISSAS!M15 -> -20466.258 | F13: =E13/E$3 -> -0.10233129 | G13: =-G3/PREMISSAS!$C$12*PREMISSAS!$C$27*PREMISSAS!$M$15 -> -25582.822 | H13: =G13/G$3 -> -0.10233129 | I13: =-I3/PREMISSAS!$C$12*PREMISSAS!$C$27*PREMISSAS!$M$15 -> -30699.387 | J13: =I13/I$3 -> -0.10233129 | K13: =-K3/PREMISSAS!$C$12*PREMISSAS!$C$27*PREMISSAS!$M$15 -> -35815.951 | L13: =K13/K$3 -> -0.10233129
B14: = Custo de Pessoal | C14: =SUM(C12:C13) -> -35529.693 | D14: =C14/C$3 -> -0.23686462 | E14: =SUM(E12:E13) -> -43682.258 | F14: =E14/E$3 -> -0.21841129 | G14: =SUM(G12:G13) -> -53798.822 | H14: =G14/G$3 -> -0.21519529 | I14: =SUM(I12:I13) -> -61951.387 | J14: =I14/I$3 -> -0.20650462 | K14: =SUM(K12:K13) -> -70103.951 | L14: =K14/K$3 -> -0.200297
B15: = Custo de Ocupação | C15: =-C3*PREMISSAS!$I$18 -> -7500 | D15: =C15/C$3 -> -0.05 | E15: =-E3*PREMISSAS!$I$18 -> -10000 | F15: =E15/E$3 -> -0.05 | G15: =-G3*PREMISSAS!$I$18 -> -12500 | H15: =G15/G$3 -> -0.05 | I15: =-I3*PREMISSAS!$I$18 -> -15000 | J15: =I15/I$3 -> -0.05 | K15: =-K3*PREMISSAS!$I$18 -> -17500 | L15: =K15/K$3 -> -0.05
B16: = Custo de Manutenção de Máquinas e Equipamentos | C16: =-PREMISSAS!$I$23 -> -2000 | D16: =C16/C$3 -> -0.013333333 | E16: =-PREMISSAS!$I$23 -> -2000 | F16: =E16/E$3 -> -0.01 | G16: =-PREMISSAS!$I$23 -> -2000 | H16: =G16/G$3 -> -0.008 | I16: =-PREMISSAS!$I$23 -> -2000 | J16: =I16/I$3 -> -0.0066666667 | K16: =-PREMISSAS!$I$23 -> -2000 | L16: =K16/K$3 -> -0.0057142857
B17: (-) Plataforma Agregadores (Taxas Ifood e Rappi) | C17: =-C5*PREMISSAS!$C$23*PREMISSAS!$I$28 -> -6411.4344 | D17: =C17/C$3 -> -0.042742896 | E17: =-E5*PREMISSAS!$C$23*PREMISSAS!$I$28 -> -8548.5791 | F17: =E17/E$3 -> -0.042742896 | G17: =-G5*PREMISSAS!$C$23*PREMISSAS!$I$28 -> -10685.724 | H17: =G17/G$3 -> -0.042742896 | I17: =-I5*PREMISSAS!$C$23*PREMISSAS!$I$28 -> -12822.869 | J17: =I17/I$3 -> -0.042742896 | K17: =-K5*PREMISSAS!$C$23*PREMISSAS!$I$28 -> -14960.013 | L17: =K17/K$3 -> -0.042742896
B18: (-) Custo Cartão Crédito (Máquina e Transações) | C18: =(-C5*(PREMISSAS!$C$20+PREMISSAS!$C$21)*PREMISSAS!$I$30)+(-C5*PREMISSAS!$C$22*PREMISSAS!$I$29) -> -1661.7644 | D18: =C18/C$3 -> -0.011078429 | E18: =(-E5*(PREMISSAS!$C$20+PREMISSAS!$C$21)*PREMISSAS!$I$30)+(-E5*PREMISSAS!$C$22*PREMISSAS!$I$29) -> -2215.6859 | F18: =E18/E$3 -> -0.011078429 | G18: =(-G5*(PREMISSAS!$C$20+PREMISSAS!$C$21)*PREMISSAS!$I$30)+(-G5*PREMISSAS!$C$22*PREMISSAS!$I$29) -> -2769.6074 | H18: =G18/G$3 -> -0.011078429 | I18: =(-I5*(PREMISSAS!$C$20+PREMISSAS!$C$21)*PREMISSAS!$I$30)+(-I5*PREMISSAS!$C$22*PREMISSAS!$I$29) -> -3323.5288 | J18: =I18/I$3 -> -0.011078429 | K18: =(-K5*(PREMISSAS!$C$20+PREMISSAS!$C$21)*PREMISSAS!$I$30)+(-K5*PREMISSAS!$C$22*PREMISSAS!$I$29) -> -3877.4503 | L18: =K18/K$3 -> -0.011078429 | M18: INCLUIR ALUGUEL DE MÁQUINAS
B19: = Custos Terceiros | C19: =SUM(C17:C18) -> -8073.1988 | D19: =C19/C$3 -> -0.053821325 | E19: =SUM(E17:E18) -> -10764.265 | F19: =E19/E$3 -> -0.053821325 | G19: =SUM(G17:G18) -> -13455.331 | H19: =G19/G$3 -> -0.053821325 | I19: =SUM(I17:I18) -> -16146.398 | J19: =I19/I$3 -> -0.053821325 | K19: =SUM(K17:K18) -> -18837.464 | L19: =K19/K$3 -> -0.053821325
B20: (-) Custo Telefone e Internet | C20: =-PREMISSAS!$P$12 -> -500 | D20: =C20/C$3 -> -0.0033333333 | E20: =-PREMISSAS!$P$12 -> -500 | F20: =E20/E$3 -> -0.0025 | G20: =-PREMISSAS!$P$12 -> -500 | H20: =G20/G$3 -> -0.002 | I20: =-PREMISSAS!$P$12 -> -500 | J20: =I20/I$3 -> -0.0016666667 | K20: =-PREMISSAS!$P$12 -> -500 | L20: =K20/K$3 -> -0.0014285714 | M20: incluir sonnax
B21: (-) Custo GCOM | C21: =-PREMISSAS!$P$13 -> -600 | D21: =C21/C$3 -> -0.004 | E21: =-PREMISSAS!$P$13 -> -600 | F21: =E21/E$3 -> -0.003 | G21: =-PREMISSAS!$P$13 -> -600 | H21: =G21/G$3 -> -0.0024 | I21: =-PREMISSAS!$P$13 -> -600 | J21: =I21/I$3 -> -0.002 | K21: =-PREMISSAS!$P$13 -> -600 | L21: =K21/K$3 -> -0.0017142857 | M21: avaliar custo do toten
B22: (-) Custo Água e Esgoto | C22: =-PREMISSAS!$P$14 -> -1250 | D22: =C22/C$3 -> -0.0083333333 | E22: =-PREMISSAS!$P$14 -> -1250 | F22: =E22/E$3 -> -0.00625 | G22: =-PREMISSAS!$P$14 -> -1250 | H22: =G22/G$3 -> -0.005 | I22: =-PREMISSAS!$P$14 -> -1250 | J22: =I22/I$3 -> -0.0041666667 | K22: =-PREMISSAS!$P$14 -> -1250 | L22: =K22/K$3 -> -0.0035714286
B23: (-) Custo Energia Elétrica | C23: =-PREMISSAS!$P$15 -> -4000 | D23: =C23/C$3 -> -0.026666667 | E23: =-PREMISSAS!$P$15 -> -4000 | F23: =E23/E$3 -> -0.02 | G23: =-PREMISSAS!$P$15 -> -4000 | H23: =G23/G$3 -> -0.016 | I23: =-PREMISSAS!$P$15 -> -4000 | J23: =I23/I$3 -> -0.013333333 | K23: =-PREMISSAS!$P$15 -> -4000 | L23: =K23/K$3 -> -0.011428571
B24: (-) Custo Gás | C24: =-PREMISSAS!$P$16 -> -2800 | D24: =C24/C$3 -> -0.018666667 | E24: =-PREMISSAS!$P$16 -> -2800 | F24: =E24/E$3 -> -0.014 | G24: =-PREMISSAS!$P$16 -> -2800 | H24: =G24/G$3 -> -0.0112 | I24: =-PREMISSAS!$P$16 -> -2800 | J24: =I24/I$3 -> -0.0093333333 | K24: =-PREMISSAS!$P$16 -> -2800 | L24: =K24/K$3 -> -0.008
B25: (-) Material uso e consumo | C25: =-C3*PREMISSAS!$P$17 -> -3000 | D25: =C25/C$3 -> -0.02 | E25: =-E3*PREMISSAS!$P$17 -> -4000 | F25: =E25/E$3 -> -0.02 | G25: =-G3*PREMISSAS!$P$17 -> -5000 | H25: =G25/G$3 -> -0.02 | I25: =-I3*PREMISSAS!$P$17 -> -6000 | J25: =I25/I$3 -> -0.02 | K25: =-K3*PREMISSAS!$P$17 -> -7000 | L25: =K25/K$3 -> -0.02
B26: = Custo Utilidades | C26: =SUM(C20:C25) -> -12150 | D26: =C26/C$3 -> -0.081 | E26: =SUM(E20:E25) -> -13150 | F26: =E26/E$3 -> -0.06575 | G26: =SUM(G20:G25) -> -14150 | H26: =G26/G$3 -> -0.0566 | I26: =SUM(I20:I25) -> -15150 | J26: =I26/I$3 -> -0.0505 | K26: =SUM(K20:K25) -> -16150 | L26: =K26/K$3 -> -0.046142857
B27: (-) Royalties Venda | C27: =-C3*PREMISSAS!$P$22 -> -9000 | D27: =C27/C$3 -> -0.06 | E27: =E3*-6% -> -12000 | F27: =E27/E$3 -> -0.06 | G27: =G3*-6% -> -15000 | H27: =G27/G$3 -> -0.06 | I27: =I3*-6% -> -18000 | J27: =I27/I$3 -> -0.06 | K27: =K3*-6% -> -21000 | L27: =K27/K$3 -> -0.06
B28: (-) Royalties Taxa de Entrega | C28: =-C4*PREMISSAS!$P$23 -> -552.58896 | D28: =C28/C$3 -> -0.0036839264 | E28: =-E4*PREMISSAS!$P$23 -> -736.78528 | F28: =E28/E$3 -> -0.0036839264 | G28: =-G4*PREMISSAS!$P$23 -> -920.9816 | H28: =G28/G$3 -> -0.0036839264 | I28: =-I4*PREMISSAS!$P$23 -> -1105.1779 | J28: =I28/I$3 -> -0.0036839264 | K28: =-K4*PREMISSAS!$P$23 -> -1289.3742 | L28: =K28/K$3 -> -0.0036839264
B29: (-) Pedido online + Fundo Ifood | C29: =(-C3/PREMISSAS!$C$12*PREMISSAS!$C$22*PREMISSAS!$P$24)+(-C5*PREMISSAS!$C$23*PREMISSAS!$P$25) -> -1266.692 | D29: =C29/C$3 -> -0.0084446135 | E29: =(-E3/PREMISSAS!$C$12*PREMISSAS!$C$22*PREMISSAS!$P$24)+(-E5*PREMISSAS!$C$23*PREMISSAS!$P$25) -> -1688.9227 | F29: =E29/E$3 -> -0.0084446135 | G29: =(-G3/PREMISSAS!$C$12*PREMISSAS!$C$22*PREMISSAS!$P$24)+(-G5*PREMISSAS!$C$23*PREMISSAS!$P$25) -> -2111.1534 | H29: =G29/G$3 -> -0.0084446135 | I29: =(-I3/PREMISSAS!$C$12*PREMISSAS!$C$22*PREMISSAS!$P$24)+(-I5*PREMISSAS!$C$23*PREMISSAS!$P$25) -> -2533.384 | J29: =I29/I$3 -> -0.0084446135 | K29: =-K3/PREMISSAS!$C$12*PREMISSAS!$C$22*PREMISSAS!$P$24 -> -2319.0184 | L29: =K29/K$3 -> -0.0066257669
B30: (-) Taxa de Manutenção e Adesão aos sistemas (PULSE, GOLO e Ambiente Online) | C30: =-PREMISSAS!$P$26 -> -1800 | D30: =C30/C$3 -> -0.012 | E30: =-PREMISSAS!$P$26 -> -1800 | F30: =E30/E$3 -> -0.009 | G30: =-PREMISSAS!$P$26 -> -1800 | H30: =G30/G$3 -> -0.0072 | I30: =-PREMISSAS!$P$26 -> -1800 | J30: =I30/I$3 -> -0.006 | K30: =-PREMISSAS!$P$26 -> -1800 | L30: =K30/K$3 -> -0.0051428571
B31: = Royalties e Repasse DPI | C31: =SUM(C27:C30) -> -12619.281 | D31: =C31/C$3 -> -0.08412854 | E31: =SUM(E27:E30) -> -16225.708 | F31: =E31/E$3 -> -0.08112854 | G31: =SUM(G27:G30) -> -19832.135 | H31: =G31/G$3 -> -0.07932854 | I31: =SUM(I27:I30) -> -23438.562 | J31: =I31/I$3 -> -0.07812854 | K31: =SUM(K27:K30) -> -26408.393 | L31: =K31/K$3 -> -0.07545255
B32: (-) Taxas e Licenças (Anvisa, Corpo de Bombeiros, Prefeitura e outras) | D32: =C32/C$3 -> 0 | F32: =E32/E$3 -> 0 | H32: =G32/G$3 -> 0 | J32: =I32/I$3 -> 0 | L32: =K32/K$3 -> 0
B33: = Taxas e Licenças | C33: =C32 -> 0 | D33: =C33/C$3 -> 0 | E33: =E32 -> 0 | F33: =E33/E$3 -> 0 | G33: =G32 -> 0 | H33: =G33/G$3 -> 0 | I33: =I32 -> 0 | J33: =I33/I$3 -> 0 | K33: =K32 -> 0 | L33: =K33/K$3 -> 0
B34: (-) Contador | C34: -2000 | D34: =C34/C$3 -> -0.013333333 | E34: -2000 | F34: =E34/E$3 -> -0.01 | G34: -2000 | H34: =G34/G$3 -> -0.008 | I34: -2000 | J34: =I34/I$3 -> -0.0066666667 | K34: -2000 | L34: =K34/K$3 -> -0.0057142857
B35: = Outros Custos Operacionais | C35: =C34 -> -2000 | D35: =C35/C$3 -> -0.013333333 | E35: =E34 -> -2000 | F35: =E35/E$3 -> -0.01 | G35: =G34 -> -2000 | H35: =G35/G$3 -> -0.008 | I35: =I34 -> -2000 | J35: =I35/I$3 -> -0.0066666667 | K35: =K34 -> -2000 | L35: =K35/K$3 -> -0.0057142857
B37: = Totais Custos Operacionais | C37: =SUM(C35,C33,C31,C26,C19,C16,C15,C14) -> -79872.173 | D37: =C37/C$3 -> -0.53248115 | E37: =SUM(E35,E33,E31,E26,E19,E16,E15,E14) -> -97822.231 | F37: =E37/E$3 -> -0.48911115 | G37: =SUM(G35,G33,G31,G26,G19,G16,G15,G14) -> -117736.29 | H37: =G37/G$3 -> -0.47094515 | I37: =SUM(I35,I33,I31,I26,I19,I16,I15,I14) -> -135686.35 | J37: =I37/I$3 -> -0.45228782 | K37: =SUM(K35,K33,K31,K26,K19,K16,K15,K14) -> -152999.81 | L37: =K37/K$3 -> -0.43714231
B39: (-) Fundo de Marketing (AD Fund) | C39: =-C3*PREMISSAS!$P$31 -> -6000 | D39: =C39/C$3 -> -0.04 | E39: =-E3*PREMISSAS!$P$31 -> -8000 | F39: =E39/E$3 -> -0.04 | G39: =-G3*PREMISSAS!$P$31 -> -10000 | H39: =G39/G$3 -> -0.04 | I39: =-I3*PREMISSAS!$P$31 -> -12000 | J39: =I39/I$3 -> -0.04 | K39: =-K3*PREMISSAS!$P$31 -> -14000 | L39: =K39/K$3 -> -0.04
B40: = Marketing | C40: =SUM(C39:C39) -> -6000 | D40: =C40/C$3 -> -0.04 | E40: =SUM(E39:E39) -> -8000 | F40: =E40/E$3 -> -0.04 | G40: =SUM(G39:G39) -> -10000 | H40: =G40/G$3 -> -0.04 | I40: =SUM(I39:I39) -> -12000 | J40: =I40/I$3 -> -0.04 | K40: =SUM(K39:K39) -> -14000 | L40: =K40/K$3 -> -0.04
B42: = Despesas Comerciais | C42: =C40 -> -6000 | D42: =C42/C$3 -> -0.04 | E42: =E40 -> -8000 | F42: =E42/E$3 -> -0.04 | G42: =G40 -> -10000 | H42: =G42/G$3 -> -0.04 | I42: =I40 -> -12000 | J42: =I42/I$3 -> -0.04 | K42: =K40 -> -14000 | L42: =K42/K$3 -> -0.04
B44: = EBITDA | C44: =C37+C42+C11 -> 10572.847 | D44: =C44/C$3 -> 0.070485644 | E44: =E37+E42+E11 -> 20346.129 | F44: =E44/E$3 -> 0.10173064 | G44: =G37+G42+G11 -> 28155.411 | H44: =G44/G$3 -> 0.11262164 | I44: =I37+I42+I11 -> 46982.439 | J44: =I44/I$3 -> 0.15660813 | K44: =K37+K42+K11 -> 54863.775 | L44: =K44/K$3 -> 0.15675364

Sheet PREMISSAS
B2: PREMISSAS
B3: DRE PADRÃO - REDE
B5: Orientações
B6: Preencher apenas células amarelas
B7: Premissas críticas
B9: >>> RECEITA BRUTA | E9: >>> DEDUTORES DA RECEITA | H9: >>> CMV + FRETE | K9: >>> PESSOAL | O9: >>> UTILIDADES
B11: TICKET MÉDIO | E11: PROPORÇÃO PRODUTOS | H11: CMV + FRETE | K11: HEADCOUNT E CUSTO | O11: UTILIDADES
B12: TM | C12: 81.5 | E12: Pizzas salgadas e doces | H12: CMV IDEAL COM FRETE | I12: 0.349 | K12: 150K | L12: QNTDE | M12: CUSTO UNIT | O12: TELEFONE + INTERNET | P12: 500
E13: Bebidas | H13: DESPERDÍCIO | I13: 0.005 | K13: OPERADOR | L13: 5 | M13: 3036 | O13: GCOM | P13: 600
E14: Outras sobremesas/Sanduiches | K14: GERENTE | L14: 1 | M14: 5000 | O14: ÁGUA | P14: 1250
B15: FATURAMENTO - TAXA DE ENTREGA | H15: >>> OCUPAÇÃO | K15: ESPECIALISTA | L15: CUSTO POR ENTREGA | M15: 13.9 | O15: ENERGIA | P15: 4000
B16: Valor por entrega | C16: =M15 -> 13.9 | E16: ALÍQUOTAS - SIMPLES NACIONAL | K16: 200K | L16: QNTDE | M16: CUSTO | O16: GÁS | P16: 2800
B17: % Frete grátis | C17: 0 | E17: 150K | F17: 0.10536449 | H17: OCUPAÇÃO | K17: OPERADOR | L17: 6 | M17: 3036 | O17: MATERIAL USO E CONSUMO | P17: 0.02
E18: 200K | F18: 0.11748949 | H18: ALUGUEL + IPTU | I18: 0.05 | K18: GERENTE | L18: 1 | M18: 5000
B19: SHARE CANAIS | E19: 250K | F19: 0.12476449 | K19: ESPECIALISTA | L19: CUSTO POR ENTREGA | M19: 13.9 | O19: >>> FRANQUEADORA
B20: BALCÃO | C20: 0.16 | E20: 300K | F20: 0.099435337 | H20: >>> MANUTENÇÃO | K20: 250K | L20: QNTDE | M20: CUSTO
B21: TELEFONE | C21: 0.24 | E21: 350K | F21: 0.11443534 | K21: OPERADOR | L21: 6 | M21: 3036 | O21: FRANQUEADORA
B22: APP | C22: =100%-(SUM(C20:C21,C23)) -> 0.27 | H22: MANUTENÇÃO | K22: GERENTE | L22: 2 | M22: 5000 | O22: ROYALTIES VENDA | P22: 0.06
B23: AGREGADORES | C23: 0.33 | E23: ALÍQUOTAS - LUCRO REAL | H23: MANUTENÇÃO | I23: 2000 | K23: ESPECIALISTA | L23: CUSTO POR ENTREGA | M23: 13.9 | O23: ROYALTIES TAXA DE ENTREGA | P23: 0.036
E24: PIS | F24: 0.0165 | K24: 300K | L24: QNTDE | M24: CUSTO | O24: PULSE - PEDIDO ONLINE (tarifa) | P24: 2
B25: SHARE MÉTODO DE ENTREGA | E25: COFINS | F25: 0.076 | H25: >>> TAXAS DE CARTÃO E AGREGADORES | K25: OPERADOR | L25: 7 | M25: 3036 | O25: FUNDO IFOOD | P25: 0.005
B26: BALCÃO/CARRY OUT | C26: 0.4 | E26: ICMS | F26: 0.035 | K26: GERENTE | L26: 2 | M26: 5000 | O26: PULSE+GOLO+MAPPING FEE | P26: 1800
B27: DELIVERY | C27: 0.6 | H27: MANUTENÇÃO | K27: ESPECIALISTA | L27: CUSTO POR ENTREGA | M27: 13.9
H28: IFOOD | I28: 0.1175 | K28: 350K | L28: QNTDE | M28: CUSTO | O28: >>> ASSOCIAÇÃO
H29: ADYEN | I29: 0.015 | K29: OPERADOR | L29: 8 | M29: 3036
H30: CARTÕES | I30: 0.015 | K30: GERENTE | L30: 2 | M30: 5000 | O30: ASSOCIAÇÃO
K31: ESPECIALISTA | L31: CUSTO POR ENTREGA | M31: 13.9 | O31: FUNDO DE MARKETING | P31: 0.04

Sheet LUCRO REAL c. PIS_COFINS
B2: DEMONSTRAÇÃO DE RESULTADO DO EXERCÍCIO - DRE | C2: 150K | D2: 150K - AV% | E2: 200K | F2: 200K - AV% | G2: 250K | H2: 250K - AV% | I2: 300K | J2: 300K - AV% | K2: 400K | L2: 400K - AV%
B3: Receita Vendas | C3: 150000 | D3: =C3/C$3 -> 1 | E3: 200000 | F3: =E3/E$3 -> 1 | G3: 250000 | H3: =G3/G$3 -> 1 | I3: 300000 | J3: =I3/I$3 -> 1 | K3: 400000 | L3: =K3/K$3 -> 1
B4: Receita Serviços (Taxa de Entrega, Receita Merchandising) | C4: 9780.0101 | D4: =C4/C$3 -> 0.065200068 | E4: 13040.014 | F4: =E4/E$3 -> 0.065200068 | G4: 16300.017 | H4: =G4/G$3 -> 0.065200068 | I4: 19560.02 | J4: =I4/I$3 -> 0.065200068 | K4: 26080.027 | L4: =K4/K$3 -> 0.065200068
B5: = Receita Operacional Bruta | C5: =SUM(C3:C4) -> 159780.01 | D5: =C5/C$3 -> 1.0652001 | E5: =SUM(E3:E4) -> 213040.01 | F5: =E5/E$3 -> 1.0652001 | G5: =SUM(G3:G4) -> 266300.02 | H5: =G5/G$3 -> 1.0652001 | I5: =SUM(I3:I4) -> 319560.02 | J5: =I5/I$3 -> 1.0652001 | K5: =SUM(K3:K4) -> 426080.03 | L5: =K5/K$3 -> 1.0652001
B6: (-) Impostos (ICMS, PIS, COFINS e ISS) | C6: -18856 | D6: =C6/C$3 -> -0.12570667 | E6: -21154.873 | F6: =E6/E$3 -> -0.10577437 | G6: -26443.592 | H6: =G6/G$3 -> -0.10577437 | I6: -31732.31 | J6: =I6/I$3 -> -0.10577437 | K6: -42309.747 | L6: =K6/K$3 -> -0.10577437
B7: = Receita Líquida | C7: =SUM(C5:C6) -> 140924.01 | D7: =C7/C$3 -> 0.9394934 | E7: =SUM(E5:E6) -> 191885.14 | F7: =E7/E$3 -> 0.9594257 | G7: =SUM(G5:G6) -> 239856.43 | H7: =G7/G$3 -> 0.9594257 | I7: =SUM(I5:I6) -> 287827.71 | J7: =I7/I$3 -> 0.9594257 | K7: =SUM(K5:K6) -> 383770.28 | L7: =K7/K$3 -> 0.9594257
B8: = CMV | C8: -43914.375 | D8: =C8/C$3 -> -0.2927625 | E8: -58552.5 | F8: =E8/E$3 -> -0.2927625 | G8: -73190.625 | H8: =G8/G$3 -> -0.2927625 | I8: -87828.75 | J8: =I8/I$3 -> -0.2927625 | K8: -117105 | L8: =K8/K$3 -> -0.2927625
B9: (-) Fretes | C9: -4500 | D9: =C9/C$3 -> -0.03 | E9: -6000 | F9: =E9/E$3 -> -0.03 | G9: -7500 | H9: =G9/G$3 -> -0.03 | I9: -9000 | J9: =I9/I$3 -> -0.03 | K9: -12000 | L9: =K9/K$3 -> -0.03
B10: = CMV com Frete | C10: =C9+C8 -> -48414.375 | D10: =C10/C$3 -> -0.3227625 | E10: =E9+E8 -> -64552.5 | F10: =E10/E$3 -> -0.3227625 | G10: =G9+G8 -> -80690.625 | H10: =G10/G$3 -> -0.3227625 | I10: =I9+I8 -> -96828.75 | J10: =I10/I$3 -> -0.3227625 | K10: =K9+K8 -> -129105 | L10: =K10/K$3 -> -0.3227625
B11: = Lucro Bruto
B12: = Lucro Bruto | C12: =C7+C10 -> 92509.635 | D12: =C12/C$3 -> 0.6167309 | E12: =E7+E10 -> 127332.64 | F12: =E12/E$3 -> 0.6366632 | G12: =G7+G10 -> 159165.8 | H12: =G12/G$3 -> 0.6366632 | I12: =I7+I10 -> 190998.96 | J12: =I12/I$3 -> 0.6366632 | K12: =K7+K10 -> 254665.28 | L12: =K12/K$3 -> 0.6366632
B13: = Custo de Pessoal | C13: =SUM(C14:C15) -> 0 | D13: =C13/C$3 -> 0 | E13: =SUM(E14:E15) -> 0 | F13: =E13/E$3 -> 0 | G13: =SUM(G14:G15) -> 0 | H13: =G13/G$3 -> 0 | I13: =SUM(I14:I15) -> 0 | J13: =I13/I$3 -> 0 | K13: =SUM(K14:K15) -> 0 | L13: =K13/K$3 -> 0
B14: (-) Custo pessoal salão
B15: (-) Custo especialistas
B16: = Custo de Ocupação | C16: =-C3*5% -> -7500 | D16: =C16/C$3 -> -0.05 | E16: =-E3*5% -> -10000 | F16: =E16/E$3 -> -0.05 | G16: =-G3*5% -> -12500 | H16: =G16/G$3 -> -0.05 | I16: =-I3*5% -> -15000 | J16: =I16/I$3 -> -0.05 | K16: =-K3*5% -> -20000 | L16: =K16/K$3 -> -0.05
B17: = Custo de Manutenção de Máquinas e Equipamentos | C17: -2208.4702 | D17: =C17/C$3 -> -0.014723134 | E17: -2208.4702 | F17: =E17/E$3 -> -0.011042351 | G17: -2208.4702 | H17: =G17/G$3 -> -0.0088338806 | I17: -2208.4702 | J17: =I17/I$3 -> -0.0073615672 | K17: -2208.4702 | L17: =K17/K$3 -> -0.0055211754
B18: (-) Plataforma Agregadores (Taxas Ifood e Rappi) | C18: -7368.3791 | D18: =C18/C$3 -> -0.049122528 | E18: -9824.5055 | F18: =E18/E$3 -> -0.049122528 | G18: -12280.632 | H18: =G18/G$3 -> -0.049122528 | I18: -14736.758 | J18: =I18/I$3 -> -0.049122528 | K18: -19649.011 | L18: =K18/K$3 -> -0.049122528
B19: (-) Custo Cartão Crédito (Máquina e Transações) | C19: -1505.4757 | D19: =C19/C$3 -> -0.010036504 | E19: -2007.3009 | F19: =E19/E$3 -> -0.010036504 | G19: -2509.1261 | H19: =G19/G$3 -> -0.010036504 | I19: -3010.9513 | J19: =I19/I$3 -> -0.010036504 | K19: -4014.6018 | L19: =K19/K$3 -> -0.010036504
B20: = Custos Terceiros | C20: =SUM(C18:C19) -> -8873.8548 | D20: =C20/C$3 -> -0.059159032 | E20: =SUM(E18:E19) -> -11831.806 | F20: =E20/E$3 -> -0.059159032 | G20: =SUM(G18:G19) -> -14789.758 | H20: =G20/G$3 -> -0.059159032 | I20: =SUM(I18:I19) -> -17747.71 | J20: =I20/I$3 -> -0.059159032 | K20: =SUM(K18:K19) -> -23663.613 | L20: =K20/K$3 -> -0.059159032
B21: (-) Custo Telefone e Internet | C21: -400 | D21: =C21/C$3 -> -0.0026666667 | E21: -400 | F21: =E21/E$3 -> -0.002 | G21: -400 | H21: =G21/G$3 -> -0.0016 | I21: -400 | J21: =I21/I$3 -> -0.0013333333 | K21: -400 | L21: =K21/K$3 -> -0.001
B22: (-) Custo GCOM | C22: -600 | D22: =C22/C$3 -> -0.004 | E22: -600 | F22: =E22/E$3 -> -0.003 | G22: -600 | H22: =G22/G$3 -> -0.0024 | I22: -600 | J22: =I22/I$3 -> -0.002 | K22: -600 | L22: =K22/K$3 -> -0.0015
B23: (-) Custo Água e Esgoto | C23: -812.41985 | D23: =C23/C$3 -> -0.0054161323 | E23: -812.41985 | F23: =E23/E$3 -> -0.0040620992 | G23: -812.41985 | H23: =G23/G$3 -> -0.0032496794 | I23: -812.41985 | J23: =I23/I$3 -> -0.0027080662 | K23: -812.41985 | L23: =K23/K$3 -> -0.0020310496
B24: (-) Custo Energia Elétrica | C24: -4151.3403 | D24: =C24/C$3 -> -0.027675602 | E24: -4151.3403 | F24: =E24/E$3 -> -0.020756701 | G24: -4151.3403 | H24: =G24/G$3 -> -0.016605361 | I24: -4151.3403 | J24: =I24/I$3 -> -0.013837801 | K24: -4151.3403 | L24: =K24/K$3 -> -0.010378351
B25: (-) Custo Gás | C25: -2720.5336 | D25: =C25/C$3 -> -0.018136891 | E25: -2720.5336 | F25: =E25/E$3 -> -0.013602668 | G25: -2720.5336 | H25: =G25/G$3 -> -0.010882134 | I25: -2720.5336 | J25: =I25/I$3 -> -0.0090684454 | K25: -2720.5336 | L25: =K25/K$3 -> -0.006801334
B26: (-) Material uso e consumo | D26: =C26/C$3 -> 0 | F26: =E26/E$3 -> 0 | H26: =G26/G$3 -> 0 | J26: =I26/I$3 -> 0 | L26: =K26/K$3 -> 0
B27: = Custo Utilidades | C27: =SUM(C21:C26) -> -8684.2937 | D27: =C27/C$3 -> -0.057895291 | E27: =SUM(E21:E26) -> -8684.2937 | F27: =E27/E$3 -> -0.043421469 | G27: =SUM(G21:G26) -> -8684.2937 | H27: =G27/G$3 -> -0.034737175 | I27: =SUM(I21:I26) -> -8684.2937 | J27: =I27/I$3 -> -0.028947646 | K27: =SUM(K21:K26) -> -8684.2937 | L27: =K27/K$3 -> -0.021710734
B28: (-) Royalties Venda | C28: =C3*-6% -> -9000 | D28: =C28/C$3 -> -0.06 | E28: =E3*-6% -> -12000 | F28: =E28/E$3 -> -0.06 | G28: =G3*-6% -> -15000 | H28: =G28/G$3 -> -0.06 | I28: =I3*-6% -> -18000 | J28: =I28/I$3 -> -0.06 | K28: =K3*-6% -> -24000 | L28: =K28/K$3 -> -0.06
B29: (-) Royalties Taxa de Entrega | C29: =C4*-3.6% -> -352.08037 | D29: =C29/C$3 -> -0.0023472024 | E29: =E4*-3.6% -> -469.44049 | F29: =E29/E$3 -> -0.0023472024 | G29: =G4*-3.6% -> -586.80061 | H29: =G29/G$3 -> -0.0023472024 | I29: =I4*-3.6% -> -704.16073 | J29: =I29/I$3 -> -0.0023472024 | K29: =K4*-3.6% -> -938.88097 | L29: =K29/K$3 -> -0.0023472024
B30: (-) Taxa de Manutenção e Adesão aos sistemas (PULSE, GOLO e Ambiente Online) | D30: =C30/C$3 -> 0 | F30: =E30/E$3 -> 0 | H30: =G30/G$3 -> 0 | J30: =I30/I$3 -> 0 | L30: =K30/K$3 -> 0
B31: = Royalties e Repasse DPI | C31: =SUM(C28:C30) -> -9352.0804 | D31: =C31/C$3 -> -0.062347202 | E31: =SUM(E28:E30) -> -12469.44 | F31: =E31/E$3 -> -0.062347202 | G31: =SUM(G28:G30) -> -15586.801 | H31: =G31/G$3 -> -0.062347202 | I31: =SUM(I28:I30) -> -18704.161 | J31: =I31/I$3 -> -0.062347202 | K31: =SUM(K28:K30) -> -24938.881 | L31: =K31/K$3 -> -0.062347202
B32: (-) Taxas e Licenças (Anvisa, Corpo de Bombeiros, Prefeitura e outras) | D32: =C32/C$3 -> 0 | F32: =E32/E$3 -> 0 | H32: =G32/G$3 -> 0 | J32: =I32/I$3 -> 0 | L32: =K32/K$3 -> 0
B33: = Taxas e Licenças | C33: =C32 -> 0 | D33: =C33/C$3 -> 0 | E33: =E32 -> 0 | F33: =E33/E$3 -> 0 | G33: =G32 -> 0 | H33: =G33/G$3 -> 0 | I33: =I32 -> 0 | J33: =I33/I$3 -> 0 | K33: =K32 -> 0 | L33: =K33/K$3 -> 0
B34: (-) Outros Custos Operacionais | D34: =C34/C$3 -> 0 | F34: =E34/E$3 -> 0 | H34: =G34/G$3 -> 0 | J34: =I34/I$3 -> 0 | L34: =K34/K$3 -> 0
B35: = Outros Custos Operacionais | C35: =C34 -> 0 | D35: =C35/C$3 -> 0 | E35: =E34 -> 0 | F35: =E35/E$3 -> 0 | G35: =G34 -> 0 | H35: =G35/G$3 -> 0 | I35: =I34 -> 0 | J35: =I35/I$3 -> 0 | K35: =K34 -> 0 | L35: =K35/K$3 -> 0
B37: = Totais Custos Operacionais | C37: =SUM(C35,C33,C31,C27,C20,C17,C16,C13) -> -36618.699 | D37: =C37/C$3 -> -0.24412466 | E37: =SUM(E35,E33,E31,E27,E20,E17,E16,E13) -> -45194.011 | F37: =E37/E$3 -> -0.22597005 | G37: =SUM(G35,G33,G31,G27,G20,G17,G16,G13) -> -53769.322 | H37: =G37/G$3 -> -0.21507729 | I37: =SUM(I35,I33,I31,I27,I20,I17,I16,I13) -> -62344.634 | J37: =I37/I$3 -> -0.20781545 | K37: =SUM(K35,K33,K31,K27,K20,K17,K16,K13) -> -79495.258 | L37: =K37/K$3 -> -0.19873814
D38: =C38/C$3 -> 0 | F38: =E38/E$3 -> 0 | H38: =G38/G$3 -> 0 | J38: =I38/I$3 -> 0 | L38: =K38/K$3 -> 0
B39: (-) Propaganda, Publicidade, Brindes, Feiras e Convenções | D39: =C39/C$3 -> 0 | F39: =E39/E$3 -> 0 | H39: =G39/G$3 -> 0 | J39: =I39/I$3 -> 0 | L39: =K39/K$3 -> 0
B40: (-) Fundo de Marketing (AD Fund) | C40: =C3*-4% -> -6000 | D40: =C40/C$3 -> -0.04 | E40: =E3*-4% -> -8000 | F40: =E40/E$3 -> -0.04 | G40: =G3*-4% -> -10000 | H40: =G40/G$3 -> -0.04 | I40: =I3*-4% -> -12000 | J40: =I40/I$3 -> -0.04 | K40: =K3*-4% -> -16000 | L40: =K40/K$3 -> -0.04
B41: = Marketing | C41: =SUM(C39:C40) -> -6000 | D41: =C41/C$3 -> -0.04 | E41: =SUM(E39:E40) -> -8000 | F41: =E41/E$3 -> -0.04 | G41: =SUM(G39:G40) -> -10000 | H41: =G41/G$3 -> -0.04 | I41: =SUM(I39:I40) -> -12000 | J41: =I41/I$3 -> -0.04 | K41: =SUM(K39:K40) -> -16000 | L41: =K41/K$3 -> -0.04
B43: = Despesas Comerciais | C43: =C41 -> -6000 | D43: =C43/C$3 -> -0.04 | E43: =E41 -> -8000 | F43: =E43/E$3 -> -0.04 | G43: =G41 -> -10000 | H43: =G43/G$3 -> -0.04 | I43: =I41 -> -12000 | J43: =I43/I$3 -> -0.04 | K43: =K41 -> -16000 | L43: =K43/K$3 -> -0.04
...
